Workbook

Sheet Gen-Ind
A3: Overseas Energy Import Statement (From India): | H3: =Summary!C1 -> Month: June/2025
A5: Consigne | B5: S/N | C5: Feeder/Circuit Name | D5: Previous Reading | E5: Present Reading | F5: Difference | G5: C.F | H5: OMF | I5: Total KWh | J5: Remarks
A6: 1 | B6: 2 | C6: 3 | D6: 4 | E6: 5 | F6: 6=5-4 | G6: 7 | H6: 8 | I6: 9=6*7*8 | J6: 10
A7: Overseas Energy (From India) | B7: 1 | C7: HVC 400KV ,Exp(A+) | D7: ='Generation Reading'!C1118 -> 3392.6235 | E7: ='Generation Reading'!D1118 -> 3415.3925 | F7: =E7-D7 -> 22.769 | G7: 1 | H7: 7272727.3 | I7: ='Generation Reading'!H1118 -> 1.6559273e+08
B8: 2 | C8: HVC 400KV,Imp(A-) | D8: ='Generation Reading'!C1119 -> 0.1007 | E8: ='Generation Reading'!C1119 -> 0.1007 | F8: =E8-D8 -> 0 | G8: 1 | H8: 7272727.3 | I8: ='Generation Reading'!H1119 -> 0
B9: 3 | C9: HVC 400KV,Exp(A+) | D9: ='Generation Reading'!C1120 -> 955.5239 | E9: ='Generation Reading'!D1120 -> 978.294 | F9: =E9-D9 -> 22.7701 | G9: 1 | H9: 7272727.3 | I9: ='Generation Reading'!H1120 -> 1.6560073e+08
B10: 4 | C10: HVC 400KV,Imp(A-) | D10: 0 | E10: ='Generation Reading'!D1126 -> 0 | F10: =E10-D10 -> 0 | G10: 1 | H10: 7272727.3 | I10: ='Generation Reading'!H1121 -> 0
B11: =B10+1 -> 5 | C11: HVC 400KV,Exp(A+) | D11: ='Generation Reading'!C1122 -> 926.8858 | E11: ='Generation Reading'!D1122 -> 946.2699 | F11: =E11-D11 -> 19.3841 | G11: 1 | H11: 7272727.3 | I11: ='Generation Reading'!H1122 -> 1.4097527e+08
B12: =B11+1 -> 6 | C12: HVC 400KV,Imp(A-) | D12: ='Generation Reading'!C1123 -> 0.3717 | E12: ='Generation Reading'!D1123 -> 0.3717 | F12: =E12-D12 -> 0 | G12: 1 | H12: 7272727.3 | I12: ='Generation Reading'!H1123 -> 0
B13: =B12+1 -> 7 | C13: HVC 400KV,Exp(A+) | D13: ='Generation Reading'!C1124 -> 3242.3325 | E13: ='Generation Reading'!D1124 -> 3261.7143 | F13: =E13-D13 -> 19.3818 | G13: 1 | H13: 7272727.3 | I13: ='Generation Reading'!H1124 -> 1.4095855e+08
B14: =B13+1 -> 8 | C14: HVC 400KV,Imp(A-) | D14: ='Generation Reading'!C1125 -> 0.0159 | E14: ='Generation Reading'!D1125 -> 0.0159 | F14: =E14-D14 -> 0 | G14: 1 | H14: 7272727.3 | I14: ='Generation Reading'!H1125 -> 0
B15: 9 | C15: Comilla South, Ckt-1 | D15: ='Generation Reading'!C1127 -> 4316.809 | E15: ='Generation Reading'!D1127 -> 4330.046 | F15: =E15-D15 -> 13.237 | G15: 1 | H15: 960000 | I15: ='Generation Reading'!H1127 -> 12707520
B16: =B15+1 -> 10 | C16: Comilla South, Ckt-2 | D16: ='Generation Reading'!C1128 -> 4314.427 | E16: ='Generation Reading'!D1128 -> 4327.628 | F16: =E16-D16 -> 13.201 | G16: 1 | H16: 960000 | I16: ='Generation Reading'!H1128 -> 12672960 | K16: =I15+I16 -> 25380480
B17: H) | C17: Net Import From India Via Baharampur and Tripura Ckt : | I17: =I7+I9+I15+I16-I8-I10+I11-I12+I13-I14 -> 6.3850775e+08 | K17: =I7+I9 -> 3.3119345e+08
B19: (iii) | C19: Total Overseas Energy Import: | I19: =I17 -> 6.3850775e+08 | J19: KWh
N22: =I19+I23 -> 9.9467869e+09
A23: Total Energy Received To National Grid From Public-Private Generation and From Cross Border Interconnection: | I23: =I19+'Generation Reading'!K1114 -> 9.3082791e+09 | J23: Kwh
I30: 5.3366884e+09
I31: 5.3364651e+09
I32: =I30-I31 -> 223224

Sheet Generation Reading
A1: NET GENERATION OF DIFFERENT POWER STATION
H2: =Summary!C1 -> Month: June/2025
A3: EAUD | B3: Name of Power Station | C3: Meter No. | D3: O.M.F | E3: C.F. | F3: Previous Reading | G3: Present Reading | H3: Diffrrence KWh | I3: Previous Reading | J3: Present Reading | K3: Total KWh
F4: (KWh) | G4: (KWh) | I4: (KVARh) | J4: (KVARh)
A5: Dhaka | B5: Ghorashal Power Station,Unit-1 | C5: 127478 | D5: 10000 | E5: 0.9937 | F5: 964852.5 | G5: 964852.5 | H5: =G5-F5 -> 0 | K5: =(G5-F5)*D5*E5 -> 0
B6: Ghorashal Power Station,Unit-2 | C6: 127442 | D6: 10000 | E6: 1.00898 | F6: 921407 | G6: 921407 | H6: =G6-F6 -> 0 | K6: =(G6-F6)*D6*E6 -> 0
B7: Ghorashal Power Station,Unit-3 (Re-Powering) | F7: 0 | G7: 0 | H7: =G7-F7 -> 0 | K7: =(G7-F7)*D7*E7 -> 0
B8: Ghorashal Power Station,Unit-4(Re-Powering GT)Exp | C8: 38992608 | D8: 2875000 | E8: 1 | F8: 1107.435 | G8: 1112.856 | H8: =G8-F8 -> 5.421 | K8: =(G8-F8)*D8*E8 -> 15585375
B9: Ghorashal Power Station,Unit-4(Re-Powering GT)Imp | D9: 2875000 | E9: 1 | F9: 14.844 | G9: 15.148 | H9: =G9-F9 -> 0.304 | K9: =(G9-F9)*D9*E9 -> 874000
B10: Auxiliary For Unit-4 (Re-Powring_GT) (Self+Grid) | C10: 38992604 | D10: 196875 | E10: 1 | F10: 1118.67 | G10: 1126.31 | H10: =G10-F10 -> 7.64 | K10: =(G10-F10)*D10*E10 -> 1504125
B11: Ghorashal Power Station,Unit-5 | C11: 60748 | D11: 315000 | E11: 0.9967 | F11: 10043.75 | G11: 10043.75 | H11: =G11-F11 -> 0 | K11: =(G11-F11)*D11*E11 -> 0
B12: Ghorashal Power Station,Unit-6 | C12: 4813 | D12: 315000 | E12: 1 | F12: 9264.03 | G12: 9264.03 | H12: =G12-F12 -> 0 | K12: =(G12-F12)*D12*E12 -> 0
B13: Ghorashal Power Station,Unit-7(GT) | C13: 5466451 | D13: 1000000 | E13: 1 | F13: 6277.7401 | G13: 6292.2605 | H13: =G13-F13 -> 14.5204 | K13: =(G13-F13)*D13*E13 -> 14520400
B14: Ghorashal Power Station,Unit-7(ST) | C14: 0882 | D14: 1003636.4 | E14: 1 | F14: 2884.93 | G14: 2885.05 | H14: =G14-F14 -> 0.12 | K14: =(G14-F14)*D14*E14 -> 120436.36
B15: Ghorashal Power Station,Unit-7(GT) Exp 230/0.11 | C15: 0084 | D15: 3136363.6 | E15: 1 | F15: 1922.65 | G15: 1927.17 | H15: =G15-F15 -> 4.52 | K15: =(G15-F15)*D15*E15 -> 14176364
B16: Ghorashal Power Station,Unit-7(GT) Imp 230/0.11 | D16: 3136363.6 | E16: 1 | F16: 7.22 | G16: 7.48 | H16: =G16-F16 -> 0.26 | K16: =(G16-F16)*D16*E16 -> 815454.55
B17: Ghorashal Power Station,Unit-7(ST) Exp 230/0.11 | C17: 0080 | D17: 1254545.4 | E17: 1 | F17: 2138.84 | G17: 2138.92 | H17: =G17-F17 -> 0.08 | K17: =(G17-F17)*D17*E17 -> 100363.64
B18: Ghorashal Power Station,Unit-7(ST) Imp 230/0.11 | D18: 1254545.4 | E18: 1 | F18: 29.01 | G18: 29.94 | H18: =G18-F18 -> 0.93 | K18: =(G18-F18)*D18*E18 -> 1166727.3
B19: Gross Generation | K19: =SUM(K5:K14)-K9-K9 -> 30856336
B20: 21T | C20: 127449 | D20: 1000 | E20: 1.0045 | F20: 755192.5 | G20: 755192.5 | H20: =G20-F20 -> 0 | K20: =(G20-F20)*D20*E20 -> 0
B21: 22T | C21: 127448 | D21: 1000 | E21: 1.01102 | F21: 761152.5 | G21: 761152.5 | H21: =G21-F21 -> 0 | K21: =(G21-F21)*D21*E21 -> 0
B22: 23T 3BA-9 | C22: 714095 | D22: 19800 | E22: 1.0039 | F22: 12161 | G22: 12161 | H22: =G22-F22 -> 0 | K22: =(G22-F22)*D22*E22 -> 0
B23: 23T 3BB-10 | C23: 368985 | D23: 19800 | E23: 1.0039 | F23: 12100.3 | G23: 12100.3 | H23: =G23-F23 -> 0 | K23: =(G23-F23)*D23*E23 -> 0
B24: TB-3 | C24: 279446 | D24: 6300 | E24: 1.0039 | F24: 2016.4 | G24: 2016.4 | H24: =G24-F24 -> 0 | K24: =(G24-F24)*D24*E24 -> 0
B25: 24T4BA | C25: 368984 | D25: 19800 | E25: 0.9843 | H25: =G25-F25 -> 0 | K25: =(G25-F25)*D25*E25 -> 0
B26: 24T4BB | C26: 714093 | D26: 19800 | E26: 0.9743 | H26: =G26-F26 -> 0 | K26: =(G26-F26)*D26*E26 -> 0
B27: TB-4 | C27: 176010 | D27: 6300 | E27: 0.97096 | H27: =G27-F27 -> 0 | K27: =(G27-F27)*D27*E27 -> 0
B28: 25T 5BA | C28: 770990 | D28: 19800 | E28: 0.99399 | F28: 8201.2 | G28: 8201.2 | H28: =G28-F28 -> 0 | K28: =(G28-F28)*D28*E28 -> 0
B29: 25T 5BB | C29: 770927 | D29: 19800 | E29: 0.99127 | F29: 8353.15 | G29: 8353.15 | H29: =G29-F29 -> 0 | K29: =(G29-F29)*D29*E29 -> 0
B30: TB-5 | C30: 60749 | D30: 6300 | E30: 0.9895 | F30: 7245.34 | G30: 7245.34 | H30: =G30-F30 -> 0 | K30: =(G30-F30)*D30*E30 -> 0
B31: Auxiliary For Unit-7 (GT) (Self+Grid) | D31: 181818.18 | E31: 1 | F31: 1318.38 | G31: 1321.89 | H31: =G31-F31 -> 3.51 | K31: =(G31-F31)*D31*E31 -> 638181.81
B32: Auxiliary For Unit-7 (ST) (Self+Grid) | D32: 163090.9 | E32: 1 | F32: 1426.72 | G32: 1433.33 | H32: =G32-F32 -> 6.61 | K32: =(G32-F32)*D32*E32 -> 1078030.8
B33: Auxiliary For Unit-4 (Re-Powring_GT) (Self+Grid) | K33: =K10 -> 1504125
B34: 1TR | C34: 127477 | D34: 1000 | E34: 0.9933 | F34: 120364 | G34: 120364 | H34: =G34-F34 -> 0 | K34: =(G34-F34)*D34*E34 -> 0
B35: 2TR 3(BA) | C35: 188473 | D35: 26400 | E35: 1 | F35: 9466.8 | G35: 9466.8 | H35: =G35-F35 -> 0 | K35: =(G35-F35)*D35*E35 -> 0
B36: 2TR 3(BB) | C36: 192176 | D36: 26400 | E36: 1 | F36: 4266.45 | G36: 4266.45 | H36: =G36-F36 -> 0 | K36: =(G36-F36)*D36*E36 -> 0
B37: 3TR 3(5BA) | C37: 770971 | D37: 26400 | E37: 1 | F37: 9757.25 | G37: 9760 | H37: =G37-F37 -> 2.75 | K37: =(G37-F37)*D37*E37 -> 72600
B38: 3TR 3(5BB) | C38: 184090 | D38: 26400 | E38: 1 | F38: 9009 | G38: 9011.05 | H38: =G38-F38 -> 2.05 | K38: =(G38-F38)*D38*E38 -> 54120
B39: 3TR 3(6BA) | D39: 26400 | E39: 1 | F39: 1725.85 | G39: 1728.16 | H39: =G39-F39 -> 2.31 | K39: =(G39-F39)*D39*E39 -> 60984
B40: 3TR 3(6BB) | D40: 26400 | E40: 1 | F40: 1395 | G40: 1395 | H40: =G40-F40 -> 0 | K40: =(G40-F40)*D40*E40 -> 0
...

Sheet GMCO Generation
A1: POWER PLANT WISE GENERATION
G2: =Summary!C1 -> Month: June/2025
A3: Sl.No. | C3: Power Plants | D3: =Comparison!D5 -> 45809 | I3: =Comparison!C5 -> 45778 | J3: Remark
D4: Voltage Level KV | E4: Fuel Type | F4: Gross Generation | G4: Station Use | H4: Net Generation | I4: Net Generation
F5: kWH | G5: kWH | H5: kWH | I5: kWH
A6: Power Plants Of BPDB
A7: 1 | C7: 60 MW Shikalbaha | F7: ='Generation Reading'!K335 -> 0 | G7: ='Generation Reading'!K338 -> 0 | H7: =F7-G7 -> 0 | I7: 0
A8: 2 | C8: Shikalbaha Peaking GT 150MW | D8: 132 | E8: Gas | F8: ='Generation Reading'!K347 -> 0 | G8: ='Generation Reading'!K350 -> 78724.8 | H8: =F8-G8 -> -78724.8 | I8: -99345.6 | K8: 1 x 150
A9: 3 | C9: Shahjibazar GTPP Unit- 8 & 9 (60MW) | D9: 132 | E9: Gas | F9: ='Generation Reading'!K601 -> 20194138 | G9: ='Generation Reading'!K602 -> 57.6 | H9: =F9-G9 -> 20194080 | I9: 17273587 | K9: 2x35 | L9: =(F10+F11+F12+F13+F14+F15+F16)+(G10-G11-G12-G13-G14-G15-G16) -> 27399995 | M9: =SUM(H10:H16) -> 27399995 | N9: ='Generation Reading'!K48 -> 27493002
A10: 4 | B10: i) | C10: Ghorasal TPP Unit-1 (55MW) | D10: 132 | E10: Gas | F10: ='Generation Reading'!K5 -> 0 | G10: ='Generation Reading'!K20+'Generation Reading'!K34 -> 0 | H10: =F10-G10 -> 0 | I10: -66551.1 | K10: 2 x 55
B11: ii) | C11: Ghorasal TPP Unit-2 (55MW) | D11: 132 | E11: Gas | F11: ='Generation Reading'!K6 -> 0 | G11: ='Generation Reading'!K21 -> 0 | H11: =F11-G11 -> 0 | I11: 0
B12: iii) | C12: Ghorasal Repowered CCPP Unit-3 (210MW) | D12: 132 | E12: Gas | F12: ='Generation Reading'!K7 -> 0 | G12: ='Generation Reading'!K42 -> 34500 | H12: =F12-G12 -> -34500 | I12: -34500 | K12: 1 x 210
B13: iv) | C13: Ghorasal Repowered CCPP Unit-4 (210MW) | D13: 132 | E13: Gas | F13: ='Generation Reading'!K8 -> 15585375 | G13: ='Generation Reading'!K9+'Generation Reading'!K43 -> 887800 | H13: =F13-G13 -> 14697575 | I13: -959330 | K13: 1 x 210
B14: v) | C14: Ghorasal TPP Unit-5 (210MW) | D14: 132 | E14: Gas | F14: ='Generation Reading'!K11 -> 0 | G14: ='Generation Reading'!K37+'Generation Reading'!K38+'Generation Reading'!K28+'Generation Reading'!K29+'Generation Reading'!K30 -> 126720 | H14: =F14-G14 -> -126720 | I14: 0 | K14: 1 x 210
B15: vi) | C15: Ghorashal Power Station,Unit-6 | D15: 132 | E15: Gas | F15: ='Generation Reading'!K12 -> 0 | G15: ='Generation Reading'!K39+'Generation Reading'!K40 -> 60984 | H15: =F15-G15 -> -60984 | I15: -81840
B16: vii) | C16: Ghorasal 365 MW CCPP Unit-7 (365MW) | D16: 132 | E16: Gas | F16: ='Generation Reading'!K13+'Generation Reading'!K14 -> 14640836 | G16: ='Generation Reading'!K31+'Generation Reading'!K32 -> 1716212.7 | H16: =F16-G16 -> 12924624 | I16: -418181.81 | K16: 1x 254+1x 126
B17: viii) | C17: Localy from Self Aux. & Re-powering of # 3&4 from grid auxiliary | F17: ='Generation Reading'!K45+'Generation Reading'!K46+'Generation Reading'!K47 -> 93007 | H17: ='Generation Reading'!K45+'Generation Reading'!K46+'Generation Reading'!K47 -> 93007 | I17: 103622
B18: Net Generation of Gorashal Power Station | F18: =SUM(F10:F17) -> 30319218 | G18: =SUM(G10:G17) -> 2826216.7 | H18: =SUM(H10:H17) -> 27493002 | I18: -1456780.9
A19: 5 | C19: Haripur GTPP 100MW | D19: 132 | E19: Gas | F19: ='Generation Reading'!K216 -> 0 | G19: ='Generation Reading'!K219 -> 2400 | H19: =F19-G19 -> -2400 | I19: -66000 | K19: 2 x 32
A20: 6 | C20: 210 MW Siddhirgonj TPP | D20: 132 | E20: Gas | F20: ='Generation Reading'!K225 -> 0 | G20: ='Generation Reading'!K228 -> 51268.8 | H20: =F20-G20 -> -51268.8 | I20: -57261.6 | K20: 1 x 210
A21: 7 | C21: Sylhet 20 MW GTPP | D21: 132 | E21: Gas | F21: ='Generation Reading'!K666 -> 4861620 | G21: ='Generation Reading'!K667 -> 16344 | H21: =F21-G21 -> 4845276 | I21: 9312030 | K21: 1 x 20 | L21: =7224000-31070 -> 7192930
A22: 8 | C22: Sylhet 150 MW CCPP | D22: 132 | E22: Gas | F22: ='Generation Reading'!K679 -> 96994896 | G22: ='Generation Reading'!K680 -> 326784 | H22: =F22-G22 -> 96668112 | I22: 1.1373173e+08 | K22: 1x142 | L22: =87680640-1655988 -> 86024652
A23: 9 | B23: i) | C23: Chattogram TPP-1 (Rauzan 210MW) | D23: 132 | E23: Gas | F23: ='Generation Reading'!K309 -> 0 | G23: ='Generation Reading'!K312+'Generation Reading'!K313-'Generation Reading'!K315 -> 1707808 | H23: =F23-G23 -> -1707808 | I23: -4911061 | K23: 1 x 210 | L23: -294400
B24: ii) | C24: Chattogram TPP-2 (Rauzan 210MW) | D24: 132 | E24: Gas | F24: ='Generation Reading'!K310 -> 10893720 | G24: ='Generation Reading'!K314 -> 0 | H24: =F24-G24 -> 10893720 | I24: 36087690 | K24: 1 x 210
A25: 10 | B25: i) | C25: Fenchugonj CCPP Phase-1 (97MW) | D25: 132 | E25: Gas | F25: ='Generation Reading'!K638+'Generation Reading'!K639+'Generation Reading'!K640 -> 18399552 | G25: ='Generation Reading'!K645+'Generation Reading'!K646+'Generation Reading'!K647 -> 85752 | H25: =F25-G25 -> 18313800 | I25: 24326292 | K25: 2x32+1x33 | L25: =16504000-226744 -> 16277256 | N25: =H25+H26 -> 30505068
B26: ii) | C26: Fenchugonj CCPP Phase-2 (104MW) | D26: 132 | E26: Gas | F26: ='Generation Reading'!K641+'Generation Reading'!K642+'Generation Reading'!K643 -> 13954764 | G26: ='Generation Reading'!K648+'Generation Reading'!K649+'Generation Reading'!K650+'Generation Reading'!K651 -> 1763496 | H26: =F26-G26 -> 12191268 | I26: 16111896 | K26: 2x35+1x35 | L26: =12099302-1896560 -> 10202742
A27: 11 | B27: i) | C27: Baghabari 71 MW GTPP | D27: 132 | E27: Gas | F27: ='Generation Reading'!K773 -> 3035000 | G27: ='Generation Reading'!K774 -> 119000 | H27: =F27-G27 -> 2916000 | I27: -100800 | K27: 1 x 71 | L27: =245000-90800 -> 154200 | O27: =H25+H26 -> 30505068
B28: ii) | C28: Baghabari 100 MW GTPP | D28: 132 | E28: Gas | F28: ='Generation Reading'!K777 -> 0 | G28: ='Generation Reading'!K780 -> 8250 | H28: =F28-G28 -> -8250 | I28: -9520 | K28: 1 x 100 | L28: -6880
A29: 12 | C29: Chandpur 150 MW CCPP | D29: 132 | E29: Gas | F29: ='Generation Reading'!K560 -> 22691520 | G29: ='Generation Reading'!K563 -> 172608 | H29: =F29-G29 -> 22518912 | I29: 45217344 | K29: 1X106+1x57
A30: 13 | C30: Tongi 80 MW GTPP | D30: 132 | E30: Gas | F30: ='Generation Reading'!K221 -> 0 | G30: ='Generation Reading'!K222 -> 2640 | H30: =F30-G30 -> -2640 | I30: -1320 | K30: 1 x 105 | L30: =-6653 -> -6653
A31: 14 | C31: Bhola 225 MW CCPP | D31: 132 | E31: Gas | F31: ='Generation Reading'!K1069 -> 72876545 | G31: ='Generation Reading'!K1075 -> 240872.72 | H31: =F31-G31 -> 72635672 | I31: 70117172 | K31: 2x63+1x68 | L31: -610775
A32: 15 | C32: Shajibazar 330 MW CCPP | D32: 132 | E32: Gas | F32: ='Generation Reading'!K609 -> 0 | G32: ='Generation Reading'!K614 -> 138286.8 | H32: =F32-G32 -> -138286.8 | I32: -134643.6 | K32: 2x110+2x110 | L32: =14846913-1359400 -> 13487513
A33: 16 | C33: Shahjibazar 100 MW GT-1 | D33: 132 | E33: Gas | F33: ='Generation Reading'!K616 -> 138286.8 | G33: ='Generation Reading'!K617 -> 342334.09 | H33: =F33-G33 -> -204047.29 | I33: -202107.76
A34: 17 | C34: Shikalbaha 225 MW CCPP PS (Shamirpur) | D34: 132 | E34: Gas | F34: ='Generation Reading'!K383 -> 1.4093673e+08 | G34: ='Generation Reading'!K384 -> 9961.0909 | H34: =F34-G34 -> 1.4092677e+08 | I34: 76882510 | K34: 1 x 150+1 x 75
A35: 18 | C35: Bibiyana South 400MW CCPP | D35: 230 | E35: Gas | F35: ='Generation Reading'!K631 -> 2.2046545e+08 | G35: ='Generation Reading'!K632+'Generation Reading'!K633 -> 2432354.5 | H35: =F35-G35 -> 2.180331e+08 | I35: 1.7763739e+08
A36: 19 | C36: Khulna 330MW CCPP | D36: 230 | E36: Gas/HFO | F36: ='Generation Reading'!K978 -> 0 | G36: ='Generation Reading'!K981 -> 872268.23 | H36: =F36-G36 -> -872268.23 | I36: -904877.96
A37: 20 | C37: Bibiyana-III 400 MW CCPP | D37: 230 | E37: Gas | F37: ='Generation Reading'!K628 -> 2.5507828e+08 | G37: ='Generation Reading'!K629 -> 0 | H37: =F37-G37 -> 2.5507828e+08 | I37: 2.5559764e+08 | K37: 1x285
A38: PDB Total Gas | F38: =SUM(F18:F37)+F7+F8+F9 -> 9.1083973e+08 | G38: =SUM(G18:G37)+G7+G8+G9 -> 11197427 | H38: =SUM(H18:H37)+H7+H8+H9 -> 8.996423e+08 | I38: 8.3435156e+08 | K38: =F38-G38 -> 8.996423e+08
A39: 20 | C39: Karnaphuli Hydro PP Unit-1,2,3,4, 5 (230MW) | D39: 132 | E39: Hydro | F39: ='Generation Reading'!K323 -> 1.1908178e+08 | G39: ='Generation Reading'!K329 -> 212110.1 | H39: =F39-G39 -> 1.1886967e+08 | I39: 29820737 | K39: 2x40, 3x50
A40: Total Hydro | F40: =SUM(F39) -> 1.1908178e+08 | G40: =SUM(G39) -> 212110.1 | H40: =F40-G40 -> 1.1886967e+08 | I40: 29820737 | K40: =F40-G40 -> 1.1886967e+08
...

Sheet Comparison
A1: GENERATION- IMPORT COMPARISON
A3: S/N | B3: Name of the Utility/Customer | C3: Current Month Import in KWh With Last Month | E3: Difference | F3: Deviation
C5: 45778 | D5: 45809 | F5: %
A6: 1 | B6: 2 | C6: 3 | D6: 4 | E6: 5=4-3 | F6: 6=(5/3)*100
A7: 1 | B7: O & M MYMENSINGH-1 | C7: 77767952 | D7: 80785220 | E7: =D7-C7 -> 3017268 | F7: =E7/C7 -> 0.038798347
A8: 2 | B8: O & M MYMENSINGH-2 | C8: 82575241 | D8: 85342768 | E8: =D8-C8 -> 2767527 | F8: =E8/C8 -> 0.033515216
A9: 3 | B9: O & M JAMALPUR | C9: 40962102 | D9: 41423390 | E9: =D9-C9 -> 461288 | F9: =E9/C9 -> 0.011261336
A10: 4 | B10: O & M TANGAIL | C10: 72386641 | D10: 70190734 | E10: =D10-C10 -> -2195907 | F10: =E10/C10 -> -0.030335805
A11: 5 | B11: ZONE: DIST.MYMENSING | C11: 273691936 | D11: =SUM(D7:D10) -> 277742112 | E11: =D11-C11 -> 4050176 | F11: =E11/C11 -> 0.014798302
A12: 6 | B12: O & M MOULVIBAZAR | C12: 24114863 | D12: 26637571 | E12: =D12-C12 -> 2522708 | F12: =E12/C12 -> 0.10461216
A13: 7 | B13: O & M SYLHET | C13: 91376255 | D13: 98367358 | E13: =D13-C13 -> 6991103 | F13: =E13/C13 -> 0.076508968
A14: 8 | B14: ZONE: DIST.SYLHET | C14: 115491118 | D14: =SUM(D12:D13) -> 125004929 | E14: =D14-C14 -> 9513811 | F14: =E14/C14 -> 0.082376993
A15: 9 | B15: O & M COMILLA | C15: 156543039 | D15: 149151621 | E15: =D15-C15 -> -7391418 | F15: =E15/C15 -> -0.047216523
A16: 10 | B16: O & M NOAKHALI | C16: 63273654 | D16: 60430063 | E16: =D16-C16 -> -2843591 | F16: =E16/C16 -> -0.044941154
A17: 11 | B17: ZONE:DIST:COMILLA | C17: 219816693 | D17: =D15+D16 -> 209581684 | E17: =D17-C17 -> -10235009 | F17: =E17/C17 -> -0.046561564
A18: 12 | B18: O & M CTG (EAST) | C18: 117857835 | D18: 100076972 | E18: =D18-C18 -> -17780863 | F18: =E18/C18 -> -0.15086704
A19: 13 | B19: O & M CTG (WEST) | C19: 184467619 | D19: 156883182 | E19: =D19-C19 -> -27584437 | F19: =E19/C19 -> -0.14953539
A20: 14 | B20: O & M CTG (NORTH) | C20: 71668021 | D20: 63869829 | E20: =D20-C20 -> -7798192 | F20: =E20/C20 -> -0.10880993
A21: 15 | B21: O & M CTG (SOUTH) | C21: 58802272 | D21: 51622307 | E21: =D21-C21 -> -7179965 | F21: =E21/C21 -> -0.12210353
A22: 16 | B22: O & M CTG (COX'S Bazar) | C22: 42355015 | D22: 38758018 | E22: =D22-C22 -> -3596997 | F22: =E22/C22 -> -0.084924937
A23: 17 | B23: RANGAMATI | C23: 37007237 | D23: 37083517 | E23: =D23-C23 -> 76280 | F23: =E23/C23 -> 0.0020612185
A24: 18 | B24: ZONE:DIST:CHITTAGONG | C24: 512157999 | D24: =SUM(D18:D23) -> 448293825 | E24: =D24-C24 -> -63864174 | F24: =E24/C24 -> -0.12469623 | G24: BPDB Rate
A25: 19 | B25: Total BPDB Zone Import | C25: 1121157746 | D25: =D24+D17+D14+D11 -> 1060622550 | E25: =D25-C25 -> -60535196 | F25: =E25/C25 -> -0.053993469 | G25: 7.2895 | H25: =D25*G25 -> 7.7314081e+09
A26: 20 | B26: Total 132&230 KV Retail Import | C26: 272136287 | D26: 2.2044575e+08 | E26: =D26-C26 -> -51690538 | F26: =E26/C26 -> -0.18994357
A27: 21 | B27: 230kV Rooppur-Baghabari Ckt-1&2 | C27: 14740075 | D27: 5018181.8 | E27: =D27-C27 -> -9721893.2 | F27: =E27/C27 -> -0.6595552
A28: 22 | B28: DPDC Import (132 & 33 KV) | C28: 1148411276 | D28: 9.4899702e+08 | E28: =D28-C28 -> -1.9941426e+08 | F28: =E28/C28 -> -0.17364359
A29: 23 | B29: DESCO Import (132 & 33 KV) | C29: 768937675 | D29: 6.7259079e+08 | E29: =D29-C29 -> -96346883 | F29: =E29/C29 -> -0.12529869
A30: 24 | B30: WZPDCL Import | C30: 4.3984344e+08 | D30: 416348143 | E30: =D30-C30 -> -23495296 | F30: =E30/C30 -> -0.053417406
A31: 25 | B31: PBS (WZPDCL Area) | C31: 9.4435111e+08 | D31: 993769293 | E31: =D31-C31 -> 49418182 | F31: =E31/C31 -> 0.052330305
A32: 26 | B32: WZPDCL areaTotal Import | C32: 1.3841945e+09 | D32: =D30+D31 -> 1410117436 | E32: =D32-C32 -> 25922886 | F32: =E32/C32 -> 0.018727776
A33: 27 | B33: NESCO Import | C33: 487632599 | D33: 501761025 | E33: =D33-C33 -> 14128426 | F33: =E33/C33 -> 0.028973506
A34: 28 | B34: PBS (NESCO Area) | C34: 986971353 | D34: 1066370426 | E34: =D34-C34 -> 79399073 | F34: =E34/C34 -> 0.080447191
A35: 29 | B35: NESCO areaTotal Import | C35: 1474603952 | D35: =D33+D34 -> 1568131451 | E35: =D35-C35 -> 93527499 | F35: =E35/C35 -> 0.063425504
A36: 30 | B36: PBS (BPDB Zons) Import | C36: 1574115244 | D36: 1690282967 | E36: =D36-C36 -> 116167723 | F36: =E36/C36 -> 0.073798741
A37: 31 | B37: Dhaka PBS - 1 Import | C37: 1.7274281e+08 | D37: 1.2587469e+08 | E37: =D37-C37 -> -46868112 | F37: =E37/C37 -> -0.2713173
A38: 32 | B38: Dhaka PBS - 2 Import | C38: 41765920 | D38: 38020118 | E38: =D38-C38 -> -3745801.5 | F38: =E38/C38 -> -0.089685598
A39: 33 | B39: Dhaka PBS - 3 Import | C39: 2.4570882e+08 | D39: 2.0580189e+08 | E39: =D39-C39 -> -39906925 | F39: =E39/C39 -> -0.16241552
A40: 34 | B40: Dhaka PBS - 4 Import | C40: 97855521 | D40: 88791023 | E40: =D40-C40 -> -9064498.2 | F40: =E40/C40 -> -0.092631443
A41: 35 | B41: Gazipur PBS Import-1 | C41: 3.2846569e+08 | D41: 2.7717982e+08 | E41: =D41-C41 -> -51285861 | F41: =E41/C41 -> -0.15613765
A42: 36 | B42: Gazipur PBS Import-2 | C42: 83989500 | D42: 76495500 | E42: =D42-C42 -> -7494000 | F42: =E42/C42 -> -0.089225439
...

Sheet Summary
A1: Summary on Generation-Sale & Transmission Loss: | C1: Month: June/2025
A2: S/N | B2: Description | C2: Energy in Kwh | D2: Remarks | E2: P-2
A3: 1 | B3: A) Import to Grid Network:
A4: 2 | B4: =Comparison!B52 -> Net Generation (Public+Private) | C4: =Comparison!D52 -> 8.6697714e+09
A5: 3 | B5: =Comparison!B53 -> Cross Border Import | C5: =Comparison!D53 -> 6.3850775e+08
A6: 5 | B6: Gross Import to Grid Network in KWH: | C6: =SUM(C4:C5) -> 9.3082791e+09
A7: 6 | B7: B) Export or Sale to Utilities:
A8: 7 | B8: Export to BPDB Distribution Zone, Mymensing | C8: =Comparison!D11 -> 277742112
A9: 8 | B9: Export to BPDB Distribution Zone, Sylhet | C9: =Comparison!D14 -> 125004929
A10: 9 | B10: Export to BPDB Distribution Zone, Comilla | C10: =Comparison!D17 -> 209581684
A11: 10 | B11: Export to BPDB Distribution Zone, Chittagong | C11: =Comparison!D24 -> 448293825
A12: 11 | B12: Export to BPDB 132KV & 230KV Retail Consumer | C12: =Comparison!D26 -> 2.2044575e+08
A13: 12 | B13: Export to DPDC (132KV & 33KV Level) | C13: =Comparison!D28 -> 9.4899702e+08
A14: 13 | B14: Export to DESCO (33KV Level) | C14: =Comparison!D29 -> 6.7259079e+08
A15: 14 | B15: Export to WZPDCL (33KV Level) | C15: =Comparison!D30 -> 416348143
A16: 15 | B16: Export to NESCO (33KV Level) | C16: =Comparison!D33 -> 501761025
A17: 16 | B17: Export to 230kV Rooppur-Baghabari Ckt-1&2 | C17: =Comparison!D27 -> 5018181.8
A18: 17 | B18: Export to REB (80 Nos PBSs) at 33KV Level | C18: =Comparison!D50+Comparison!D36+Comparison!D34+Comparison!D31 -> 5.2348112e+09
A19: 18 | B19: Total Sale to Utilities and 132KV Retail Consumer: | C19: =C8+C9+C10+C11+C12+C13+C14+C15+C16+C18+C17 -> 9.0605946e+09
A20: 19 | B20: Import-Sale Balance [A-B] : | C20: =C6-C19 -> 2.476845e+08
A21: 20 | B21: Percentage of Transmission Loss: | C21: =C20/C6 -> 0.026609054
C24: =C18-Comparison!D50 -> 3750422686
C25: =C24*5.8925 -> 2.2099366e+10
C26: =Comparison!D50 -> 1.4843885e+09
C27: =C26*5.8925 -> 8.7467591e+09
C28: =C27+C25 -> 3.0846125e+10
C29: দ
C31: Superintending Engineer
C32: EAU, BPDB, Dhaka

Sheet EAUD'S
D2: =Summary!C1 -> Month: June/2025 | G2: ='GMCO Generation'!I3 -> 45778
A3: SL | B3: EAUD | C3: Power Plant Name | D3: Gross Generation | E3: Station Use | F3: Net Genetation | G3: Net Generation
A4: 1 | B4: Dhaka | C4: ='GMCO Generation'!C120 -> Meghnaghat 450 MW CCPP(MPL) | D4: ='GMCO Generation'!F120 -> 2.6523064e+08 | E4: ='GMCO Generation'!G120 -> 0 | F4: ='GMCO Generation'!H120 -> 2.6523064e+08 | G4: ='GMCO Generation'!I120 -> 2.6025588e+08 | H4: =(F4-G4)/G4 -> 0.019114881 | I4: 2.5775057e+08 | J4: =F4-I4 -> 7480068
A5: 2 | C5: ='GMCO Generation'!C119 -> Haripur 360MW CCPP(HPL) | D5: ='GMCO Generation'!F119 -> 0 | E5: ='GMCO Generation'!G119 -> 0 | F5: ='GMCO Generation'!H119 -> 0 | G5: ='GMCO Generation'!I119 -> 0 | H5: =(F5-G5)/G5 -> #DIV/0! | I5: -360830 | J5: =F5-I5 -> 360830
A6: 3 | C6: ='GMCO Generation'!C132 -> NEPC Consortium Power Ltd. | D6: ='GMCO Generation'!F132 -> 0 | E6: ='GMCO Generation'!G132 -> 0 | F6: ='GMCO Generation'!H132 -> 0 | G6: ='GMCO Generation'!I132 -> 0 | H6: =(F6-G6)/G6 -> #DIV/0! | I6: -2700 | J6: =F6-I6 -> 2700
A7: 4 | C7: ='GMCO Generation'!C99 -> Siddirganj 335MW CCPP EGCB Ltd. | D7: ='GMCO Generation'!F99 -> 1.5885727e+08 | E7: ='GMCO Generation'!G99 -> 374294.83 | F7: ='GMCO Generation'!H99 -> 1.5848298e+08 | G7: ='GMCO Generation'!I99 -> 1.9909142e+08 | H7: =(F7-G7)/G7 -> -0.20396885 | I7: 1.5851333e+08 | J7: =F7-I7 -> -30353.939
A8: 5 | C8: ='GMCO Generation'!C224 -> Madanganj 102 PP(Summit) | D8: ='GMCO Generation'!F224 -> 0 | E8: ='GMCO Generation'!G224 -> 0 | F8: ='GMCO Generation'!H224 -> 0 | G8: ='GMCO Generation'!I224 -> 0 | H8: =(F8-G8)/G8 -> #DIV/0! | I8: 31303762 | J8: =F8-I8 -> -31303762
A9: 6 | C9: ='GMCO Generation'!C226 -> Siddhirganj 100 PP(Dutch Bangla) | D9: ='GMCO Generation'!F226 -> 0 | E9: ='GMCO Generation'!G226 -> 47865.6 | F9: ='GMCO Generation'!H226 -> -47865.6 | G9: ='GMCO Generation'!I226 -> -52080 | H9: =(F9-G9)/G9 -> -0.080921659 | I9: 12846230 | J9: =F9-I9 -> -12894096
A10: 7 | C10: ='GMCO Generation'!C225 -> Meghnaghat 100 MW (IEL) | D10: ='GMCO Generation'!F225 -> 0 | E10: ='GMCO Generation'!G225 -> 71232 | F10: ='GMCO Generation'!H225 -> -71232 | G10: ='GMCO Generation'!I225 -> -69024 | H10: =(F10-G10)/G10 -> 0.031988873 | I10: 14562816 | J10: =F10-I10 -> -14634048
A11: 8 | C11: ='GMCO Generation'!C199 -> Ghorashal 78.5 MW PP(MAX) | D11: ='GMCO Generation'!F199 -> 0 | E11: ='GMCO Generation'!G199 -> 0 | F11: ='GMCO Generation'!H199 -> 0 | G11: ='GMCO Generation'!I199 -> 0 | H11: =(F11-G11)/G11 -> #DIV/0! | J11: =F11-I11 -> 0
A12: 9 | C12: ='GMCO Generation'!C229 -> Keraniganj 100 MW PP (Powerpac) | D12: ='GMCO Generation'!F229 -> 0 | E12: ='GMCO Generation'!G229 -> 42696 | F12: ='GMCO Generation'!H229 -> -42696 | G12: ='GMCO Generation'!I229 -> -47520 | H12: =(F12-G12)/G12 -> -0.10151515 | I12: 1371960 | J12: =F12-I12 -> -1414656
A13: 10 | C13: ='GMCO Generation'!C94 -> Siddhirganj 2*120 MW GTPP, EGCB Ltd. | D13: ='GMCO Generation'!F94 -> 9805334.4 | E13: ='GMCO Generation'!G94 -> 70713.6 | F13: ='GMCO Generation'!H94 -> 9734620.8 | G13: ='GMCO Generation'!I94 -> 1730582.4 | H13: =(F13-G13)/G13 -> 4.6250548 | I13: 18883699 | J13: =F13-I13 -> -9149078.4
A14: 11 | C14: ='GMCO Generation'!C95 -> Haripur 412 MW CCPP,EGCB Ltd. | D14: ='GMCO Generation'!F95 -> 2.5856867e+08 | E14: ='GMCO Generation'!G95 -> 0 | F14: ='GMCO Generation'!H95 -> 2.5856867e+08 | G14: ='GMCO Generation'!I95 -> 2.5820388e+08 | H14: =(F14-G14)/G14 -> 0.0014127905 | I14: 2.6696599e+08 | J14: =F14-I14 -> -8397324
A15: 12 | C15: ='GMCO Generation'!C103 -> Gazipur 52 MW PP (RPCL) | D15: ='GMCO Generation'!F103 -> 12115224 | E15: ='GMCO Generation'!G103 -> 15945.6 | F15: ='GMCO Generation'!H103 -> 12099278 | G15: ='GMCO Generation'!I103 -> 12218242 | H15: =(F15-G15)/G15 -> -0.0097365238 | I15: 4725048 | J15: =F15-I15 -> 7374230.4
C16: ='GMCO Generation'!C235 -> B-R Powergen Ltd. Sreepur 150MW | D16: ='GMCO Generation'!F235 -> 45431520 | E16: ='GMCO Generation'!G235 -> 31080 | F16: ='GMCO Generation'!H235 -> 45400440 | G16: ='GMCO Generation'!I235 -> 51898080 | H16: =(F16-G16)/G16 -> -0.12520001 | I16: -106320 | J16: =F16-I16 -> 45506760
A17: 13 | C17: ='GMCO Generation'!C106 -> Gazipur 105 MW PP (RPCL) | D17: ='GMCO Generation'!F106 -> 30359808 | E17: ='GMCO Generation'!G106 -> 28358.4 | F17: ='GMCO Generation'!H106 -> 30331450 | G17: ='GMCO Generation'!I106 -> 25266960 | H17: =(F17-G17)/G17 -> 0.20043921 | I17: 19159699 | J17: =F17-I17 -> 11171750
A18: 14 | C18: ='GMCO Generation'!C126 -> Meghnaghat CCPP(Summit) (335MW) | D18: ='GMCO Generation'!F126 -> 1.5694462e+08 | E18: ='GMCO Generation'!G126 -> 0 | F18: ='GMCO Generation'!H126 -> 1.5694462e+08 | G18: ='GMCO Generation'!I126 -> 1.9115745e+08 | H18: =(F18-G18)/G18 -> -0.17897721 | I18: 1.3970759e+08 | J18: =F18-I18 -> 17237036
A19: 15 | C19: ='GMCO Generation'!C134 -> Gagnagar 102 MW PP (Digital Power ) | D19: ='GMCO Generation'!F134 -> 984380.4 | E19: ='GMCO Generation'!G134 -> 114076.8 | F19: ='GMCO Generation'!H134 -> 870303.6 | G19: ='GMCO Generation'!I134 -> 5525823.6 | H19: =(F19-G19)/G19 -> -0.84250246 | I19: 13193150 | J19: =F19-I19 -> -12322847
A20: 16 | C20: ='GMCO Generation'!C121 -> Ghorashal 108MW PP (Regent) | D20: ='GMCO Generation'!F121 -> 5639443.2 | E20: ='GMCO Generation'!G121 -> 63276.137 | F20: ='GMCO Generation'!H121 -> 5576167.1 | G20: ='GMCO Generation'!I121 -> -320902.27 | H20: =(F20-G20)/G20 -> -18.376527 | I20: -133635.23 | J20: =F20-I20 -> 5709802.3
A21: 17 | C21: ='GMCO Generation'!C138 -> Katpotti 52 MW PP (Sinha) | D21: ='GMCO Generation'!F138 -> 0 | E21: ='GMCO Generation'!G138 -> 94512 | F21: ='GMCO Generation'!H138 -> -94512 | G21: ='GMCO Generation'!I138 -> -104640 | H21: =(F21-G21)/G21 -> -0.096788991 | I21: -123216 | J21: =F21-I21 -> 28704
A22: 18 | C22: ='GMCO Generation'!C105 -> Kodda 150MW PP (BPDB-RPCL) | D22: ='GMCO Generation'!F105 -> 39500506 | E22: ='GMCO Generation'!G105 -> 103291.2 | F22: ='GMCO Generation'!H105 -> 39397214 | G22: ='GMCO Generation'!I105 -> 56365882 | H22: =(F22-G22)/G22 -> -0.30104501 | I22: 39956669 | J22: =F22-I22 -> -559454.4
A23: 19 | C23: ='GMCO Generation'!C140 -> Madanganj-55 MW PP(Summit) | D23: ='GMCO Generation'!F140 -> 2433230.3 | E23: ='GMCO Generation'!G140 -> 142623.6 | F23: ='GMCO Generation'!H140 -> 2290606.7 | G23: ='GMCO Generation'!I140 -> 8542806.9 | H23: =(F23-G23)/G23 -> -0.7318672 | I23: 23081040 | J23: =F23-I23 -> -20790434
A24: 20 | C24: ='GMCO Generation'!C142 -> Nababganj 55 MW PP (Southern power) | D24: ='GMCO Generation'!F142 -> 4511665.3 | E24: ='GMCO Generation'!G142 -> 56085.18 | F24: ='GMCO Generation'!H142 -> 4455580.2 | G24: ='GMCO Generation'!I142 -> 9744378.7 | H24: =(F24-G24)/G24 -> -0.5427538 | I24: 20910384 | J24: =F24-I24 -> -16454804
A25: 21 | C25: ='GMCO Generation'!C144 -> Bosila 108MW PP (CLC) | D25: ='GMCO Generation'!F144 -> 0 | E25: ='GMCO Generation'!G144 -> 0 | F25: ='GMCO Generation'!H144 -> 0 | G25: ='GMCO Generation'!I144 -> 0 | H25: =(F25-G25)/G25 -> #DIV/0! | J25: =F25-I25 -> 0
A26: 22 | C26: ='GMCO Generation'!C141 -> Manikganj 55 MW PP (Northern) | D26: ='GMCO Generation'!F141 -> 9990808.2 | E26: ='GMCO Generation'!G141 -> 53139 | F26: ='GMCO Generation'!H141 -> 9937669.2 | G26: ='GMCO Generation'!I141 -> 17109792 | H26: =(F26-G26)/G26 -> -0.41918236 | I26: 19453094 | J26: =F26-I26 -> -9515424.6
A27: 23 | C27: ='GMCO Generation'!C145 -> Kamalaghat 54 MW PP (Banco Energy) | D27: ='GMCO Generation'!F145 -> 9243252 | E27: ='GMCO Generation'!G145 -> 37584 | F27: ='GMCO Generation'!H145 -> 9205668 | G27: ='GMCO Generation'!I145 -> 15929460 | H27: =(F27-G27)/G27 -> -0.42209792 | I27: 18589932 | J27: =F27-I27 -> -9384264
A28: 24 | C28: ='GMCO Generation'!C146 -> Kodda 300 MW PP Unit-2 (Summit) | D28: ='GMCO Generation'!F146 -> 16822451 | E28: ='GMCO Generation'!G146 -> 382134.55 | F28: ='GMCO Generation'!H146 -> 16440316 | G28: ='GMCO Generation'!I146 -> 47193993 | H28: =(F28-G28)/G28 -> -0.65164388 | I28: 79569796 | J28: =F28-I28 -> -63129480
A29: 25 | C29: Reliance Bangladesh LNG & Power Ltd | D29: ='GMCO Generation'!F129 -> 85496953 | E29: ='GMCO Generation'!G129 -> 2601033.8 | F29: ='GMCO Generation'!H129 -> 82895920 | G29: ='GMCO Generation'!I129 -> -1421784.2 | H29: =(F29-G29)/G29 -> -59.304152 | I29: -1030770.3 | J29: =F29-I29 -> 83926690
A30: 26 | C30: ='GMCO Generation'!C128 -> Unique Meghnaghat 584MW CCPP | D30: ='GMCO Generation'!F128 -> 2.3653496e+08 | E30: ='GMCO Generation'!G128 -> 467448.97 | F30: ='GMCO Generation'!H128 -> 2.3606752e+08 | G30: ='GMCO Generation'!I128 -> 2.0649751e+08 | H30: =(F30-G30)/G30 -> 0.14319787 | I30: -1591008.9 | J30: =F30-I30 -> 2.3765852e+08
A31: 27 | C31: ='GMCO Generation'!C127 -> Summit Power Meghnaghat-2 583 MW CCPP | D31: ='GMCO Generation'!F127 -> 1.3077855e+08 | E31: ='GMCO Generation'!G127 -> 1110643.5 | F31: ='GMCO Generation'!H127 -> 1.296679e+08 | G31: ='GMCO Generation'!I127 -> 1.9279012e+08 | I31: -1829320.3 | J31: =F31-I31 -> 1.3149722e+08
A32: 28 | C32: ='GMCO Generation'!C174 -> Aurahati 100MW PP (Aggreko) | D32: ='GMCO Generation'!F174 -> 0 | E32: ='GMCO Generation'!G174 -> 0 | F32: ='GMCO Generation'!H174 -> 0 | G32: ='GMCO Generation'!I174 -> 0 | H32: =(F32-G32)/G32 -> #DIV/0! | J32: =F32-I32 -> 0
A33: 29 | C33: ='GMCO Generation'!C175 -> Bramhangoan 100 MW PP (Aggreko) | D33: ='GMCO Generation'!F175 -> 0 | E33: ='GMCO Generation'!G175 -> 0 | F33: ='GMCO Generation'!H175 -> 0 | G33: ='GMCO Generation'!I175 -> 0 | H33: =(F33-G33)/G33 -> #DIV/0! | J33: =F33-I33 -> 0
A34: 30 | C34: ='GMCO Generation'!C171 -> Keranigonj 300 MW PP (APR) | D34: ='GMCO Generation'!F171 -> 0 | E34: ='GMCO Generation'!G171 -> 0 | F34: ='GMCO Generation'!H171 -> 0 | G34: ='GMCO Generation'!I171 -> 0 | H34: =(F34-G34)/G34 -> #DIV/0! | J34: =F34-I34 -> 0
A35: 31 | C35: ='GMCO Generation'!C148 -> Kodda 149 MW PP Unit-1 (Summit-ACE Alliance PPL) | D35: ='GMCO Generation'!F148 -> 39102624 | E35: ='GMCO Generation'!G148 -> 51696 | F35: ='GMCO Generation'!H148 -> 39050928 | G35: ='GMCO Generation'!I148 -> 68250528 | H35: =(F35-G35)/G35 -> -0.42782966 | I35: 69791760 | J35: =F35-I35 -> -30740832
A36: 32 | C36: ='GMCO Generation'!C234 -> Manikganj 162MW Power Generation | D36: ='GMCO Generation'!F234 -> 27559037 | E36: ='GMCO Generation'!G234 -> 69955.2 | F36: ='GMCO Generation'!H234 -> 27489082 | G36: ='GMCO Generation'!I234 -> 47902968 | H36: =(F36-G36)/G36 -> -0.42615076 | I36: 60766214 | J36: =F36-I36 -> -33277133
A37: 33 | C37: ='GMCO Generation'!C164 -> Orion power Sonargaon Limited | D37: ='GMCO Generation'!F164 -> 12593376 | E37: ='GMCO Generation'!G164 -> 74304 | F37: ='GMCO Generation'!H164 -> 12519072 | G37: ='GMCO Generation'!I164 -> 15121824 | H37: =(F37-G37)/G37 -> -0.17211892 | I37: 16414272 | J37: =F37-I37 -> -3895200
A38: 34 | C38: ='GMCO Generation'!C187 -> Manikganj 35MW Spectra Solar Park Ltd. | D38: ='GMCO Generation'!F187 -> 5281838.4 | E38: ='GMCO Generation'!G187 -> 13768.8 | F38: ='GMCO Generation'!H187 -> 5268069.6 | G38: ='GMCO Generation'!I187 -> 5516049.6 | H38: =(F38-G38)/G38 -> -0.044956086 | I38: 5396784 | J38: =F38-I38 -> -128714.4
A39: 35 | C39: ='GMCO Generation'!C169 -> Kanchan Purbachol 55MW Power Generation | D39: ='GMCO Generation'!F169 -> 15558314 | E39: ='GMCO Generation'!G169 -> 25437.6 | F39: ='GMCO Generation'!H169 -> 15532877 | G39: ='GMCO Generation'!I169 -> 11879377 | H39: =(F39-G39)/G39 -> 0.30754976 | I39: 12088202 | J39: =F39-I39 -> 3444674.4
A40: 36 | C40: ='GMCO Generation'!C19 -> Haripur GTPP 100MW | D40: ='GMCO Generation'!F19 -> 0 | E40: ='GMCO Generation'!G19 -> 2400 | F40: ='GMCO Generation'!H19 -> -2400 | G40: ='GMCO Generation'!I19 -> -66000 | H40: =(F40-G40)/G40 -> -0.96363636 | I40: -90600 | J40: =F40-I40 -> 88200
A41: 37 | C41: Ghorasal PP | D41: ='GMCO Generation'!F18 -> 30319218 | E41: ='GMCO Generation'!G18 -> 2826216.7 | F41: ='GMCO Generation'!H18 -> 27493002 | G41: ='GMCO Generation'!I18 -> -1456780.9 | H41: =(F41-G41)/G41 -> -19.872434 | I41: 20473353 | J41: =F41-I41 -> 7019649
...

Sheet Diff
A4: SL | B4: EAUD | C4: ='GMCO Generation'!D3 -> 45809 | D4: =Comparison!C5 -> 45778 | E4: Diff | F4: % Ratio | G4: Division | H4: Diff
C5: Generation | D5: Generation
A6: 1 | B6: Dhaka | C6: ='EAUD''S'!F44 -> 1.600638e+09 | D6: ='EAUD''S'!G44 -> 1.7045957e+09 | E6: =C6-D6 -> -1.0395772e+08 | F6: =E6/D6 -> -0.060986732 | G6: 1193659435 | H6: =C6-G6 -> 4.0697853e+08
A7: 2 | B7: Mymensingh | C7: ='EAUD''S'!F142 -> 1.9484165e+08 | D7: ='EAUD''S'!G142 -> 1.5438024e+08 | E7: =C7-D7 -> 40461415 | F7: =E7/D7 -> 0.26208935 | G7: 157581194 | H7: =C7-G7 -> 37260456
A8: 3 | B8: Ctg-1 | C8: ='EAUD''S'!F110 -> 22559610 | D8: ='EAUD''S'!G110 -> 30253244 | E8: =C8-D8 -> -7693633.4 | F8: =E8/D8 -> -0.25430772 | G8: 44108775 | H8: =C8-G8 -> -21549165
A9: 4 | B9: Ctg-3 | C9: ='EAUD''S'!F103 -> 1.2215813e+09 | D9: ='EAUD''S'!G103 -> 1.3536035e+09 | E9: =C9-D9 -> -1.3202214e+08 | F9: =E9/D9 -> -0.097533839 | G9: 1097117977 | H9: =C9-G9 -> 1.2446333e+08
A10: 5 | B10: Cumilla | C10: ='EAUD''S'!F73 -> 1.0623916e+09 | D10: ='EAUD''S'!G73 -> 1.0908141e+09 | E10: =C10-D10 -> -28422576 | F10: =E10/D10 -> -0.026056296 | G10: 1040247716 | H10: =C10-G10 -> 22143854
A11: 6 | B11: Sylhet | C11: ='EAUD''S'!F130 -> 9.6259358e+08 | D11: ='EAUD''S'!G130 -> 9.8977235e+08 | E11: =C11-D11 -> -27178778 | F11: =E11/D11 -> -0.027459625 | G11: 1025707409 | H11: =C11-G11 -> -63113833
A12: 7 | B12: Rajshahi | C12: ='EAUD''S'!F173 -> 7.5854766e+08 | D12: ='EAUD''S'!G173 -> 8.7496314e+08 | E12: =C12-D12 -> -1.1641549e+08 | F12: =E12/D12 -> -0.13305187 | G12: 7.7996001e+08 | H12: =C12-G12 -> -21412353
A13: 8 | B13: Bogra | C13: ='EAUD''S'!F164 -> 5.7047088e+08 | D13: ='EAUD''S'!G164 -> 5.8134218e+08 | E13: =C13-D13 -> -10871305 | F13: =E13/D13 -> -0.018700354 | G13: 5.2499296e+08 | H13: =C13-G13 -> 45477912
A14: 9 | B14: Rangpur | C14: ='EAUD''S'!F187 -> 2.7089971e+08 | D14: ='EAUD''S'!G187 -> 2.1733546e+08 | E14: =C14-D14 -> 53564255 | F14: =E14/D14 -> 0.24645889 | G14: 2.6556594e+08 | H14: =C14-G14 -> 5333773.5
A15: 10 | B15: Khulna | C15: ='EAUD''S'!F201 -> 6.5230822e+08 | D15: ='EAUD''S'!G201 -> 5.7542578e+08 | E15: =C15-D15 -> 76882437 | F15: =E15/D15 -> 0.13360965 | G15: 4.1972426e+08 | H15: =C15-G15 -> 2.3258396e+08
A16: 11 | B16: Jessore | C16: ='EAUD''S'!F213 -> 7.7626197e+08 | D16: ='EAUD''S'!G213 -> 7.7524608e+08 | E16: =C16-D16 -> 1015897.4 | F16: =E16/D16 -> 0.0013104193 | G16: 821259381 | H16: =C16-G16 -> -44997406
A17: 12 | B17: Barisal | C17: ='EAUD''S'!F229 -> 1.215185e+09 | D17: ='EAUD''S'!G229 -> 1.1876593e+09 | E17: =C17-D17 -> 27525682 | F17: =E17/D17 -> 0.023176412 | G17: 1328076217 | H17: =C17-G17 -> -1.1289122e+08
C18: =SUM(C6:C17) -> 9.3082791e+09 | D18: =SUM(D6:D17) -> 9.5353911e+09 | E18: =SUM(E6:E17) -> -2.2711195e+08 | F18: =E18/D18 -> -0.023817791

Sheet SE SIR
A1: Energy Auditing Unit | P1: "
A4: SL No | B4: Description | C4: 43739 | D4: 43770 | E4: 43800 | F4: 43831 | G4: 43891 | H4: 43922 | I4: 43952 | J4: 43983 | K4: 44013 | L4: 44044 | M4: 44197 | N4: 44228 | O4: 44256
A5: 1) | B5: Generation (With Cross Border)
A6: i) | B6: Public + Privet | C6: 5.548833e+09 | D6: 4527131176 | E6: 4.3791854e+09 | F6: 4.4940189e+09 | G6: 4.4772534e+09 | H6: 4.5232446e+09 | I6: 5.0332819e+09 | J6: 5.8450889e+09 | K6: 6.3841786e+09 | L6: 6.4083653e+09 | M6: 4704480968 | N6: 4.4713463e+09 | O6: =Comparison!D52 -> 8.6697714e+09
A7: ii) | B7: Cross Border | C7: 7.1470383e+08 | D7: 471041105 | E7: 2.7216951e+08 | F7: 2.8841743e+08 | G7: 3.5099482e+08 | H7: 4.0390417e+08 | I7: 5.7626065e+08 | J7: 7.392297e+08 | K7: 7.6916937e+08 | L7: 7.7800739e+08 | M7: 529600349 | N7: 5.1068614e+08 | O7: =Comparison!D53 -> 6.3850775e+08
A8: Total Generation (With Cross Border) | C8: =SUM(C6:C7) -> 6.2635369e+09 | D8: =SUM(D6:D7) -> 4998172281 | E8: =SUM(E6:E7) -> 4.6513549e+09 | F8: =SUM(F6:F7) -> 4.7824363e+09 | G8: 4.8282482e+09 | H8: 4.9271487e+09 | I8: 5.6095426e+09 | J8: 6.5843186e+09 | K8: 7.153348e+09 | L8: 7.1863727e+09 | M8: =SUM(M6:M7) -> 5234081317 | N8: 4.9820325e+09 | O8: =SUM(O6:O7) -> 9.3082791e+09
A9: 2) | B9: Generation (Without Cross Border)
A10: i) | B10: BPDB | C10: 1.5064714e+09 | D10: 1388408579 | E10: 1.1788699e+09 | F10: 1.3732834e+09 | G10: 1.2969577e+09 | H10: 1.1155401e+09 | I10: 9.3960771e+08 | J10: 1.0497294e+09 | K10: 1.0504161e+09 | L10: 1.0431429e+09 | M10: 8.4232585e+08 | N10: 8.8573588e+08 | O10: ='GMCO Generation'!H81 -> 1.2215294e+09
A11: ii) | B11: Public Com. Ltd | C11: 1.5927622e+09 | D11: 1478173804 | E11: 1.55514e+09 | F11: 1.3923479e+09 | G11: 1.2118121e+09 | H11: 1.4412991e+09 | I11: 1.5053534e+09 | J11: 1.4014344e+09 | K11: 1.694278e+09 | L11: 1.444223e+09 | M11: 1.0732753e+09 | N11: 1.0740174e+09 | O11: ='GMCO Generation'!H92+'GMCO Generation'!H102+'GMCO Generation'!H107+'GMCO Generation'!H111+'GMCO Generation'!H114 -> 1.5396475e+09
A12: iii) | B12: IPP | C12: 2.4495994e+09 | D12: 1660548793 | E12: 1.6451754e+09 | F12: 1.7283875e+09 | G12: 1.9684836e+09 | H12: 1.9664054e+09 | I12: 2.5883208e+09 | J12: 3.393925e+09 | K12: 3.6394846e+09 | L12: 3.9209994e+09 | M12: 2.7886566e+09 | N12: 2.511593e+09 | O12: ='GMCO Generation'!H130+'GMCO Generation'!H170+'GMCO Generation'!H178+'GMCO Generation'!H194+'GMCO Generation'!H220+'GMCO Generation'!H238+'GMCO Generation'!H249+'GMCO Generation'!H274+'GMCO Generation'!H109 -> 5.0388684e+09
A13: Total Generation(Without Cross Border) | C13: =SUM(C10:C12) -> 5.548833e+09 | D13: =SUM(D10:D12) -> 4527131176 | E13: =SUM(E10:E12) -> 4.3791854e+09 | F13: =SUM(F10:F12) -> 4.4940189e+09 | G13: 4.4772534e+09 | H13: 4.5232446e+09 | I13: 5.0332819e+09 | J13: 5.8450889e+09 | K13: 6.3841786e+09 | L13: 6.4083653e+09 | M13: =SUM(M10:M12) -> 4.7042577e+09 | N13: 4.4713463e+09 | O13: =SUM(O10:O12) -> 7.8000453e+09 | P13: =O13+O7 -> 8.4385531e+09
A14: 3) | B14: Wheeling Unit | C14: 577220736 | D14: 512300460 | E14: 570973669 | F14: 415303220 | G14: 4.1719031e+08 | M14: =M17-M15 -> 363207058 | P14: =P13-O8 -> -8.6972605e+08
A15: 4) | B15: Non-Wheeling Unit | C15: 276278248 | D15: 176281713 | E15: 175149185 | F15: 185034462 | G15: 184843137 | M15: 259056964
A16: 5) | B16: Utility Sold Unit (BPDB)
A17: i) | B17: BPDB 33Kv Consumer | C17: 8.5295325e+08 | D17: 687935506 | E17: 5.9444135e+08 | F17: 6.0033768e+08 | G17: 6.0203345e+08 | H17: 6.6427692e+08 | I17: 7.5776419e+08 | J17: 8.1038834e+08 | K17: 8.7077449e+08 | L17: 8.8427519e+08 | M17: 622264022 | N17: 5.9725936e+08 | O17: =Comparison!D25 -> 1060622550
A18: ii) | B18: BPDB 132Kv Consumer | C18: 87181344 | D18: 73922952 | E18: 90197144 | F18: 95970795 | G18: 94355932 | H18: 60613752 | I18: 65471280 | J18: 92085168 | K18: 95288832 | L18: 81461940 | M18: 103487520 | N18: 88903920 | O18: 1.0013894e+08
A19: iii) | B19: BPDB 230Kv Consumer | C19: 83919057 | D19: 82699639 | E19: 76798572 | F19: 105438694 | G19: 95109600 | H19: 24221095 | I19: 77390400 | J19: 98225891 | K19: 129106109 | L19: 81976375 | M19: 155556945 | N19: 119293891 | O19: 1.2399091e+08
A20: Total BPBD | C20: =C17+C18+C19 -> 1.0240537e+09 | D20: 844558097 | E20: =E17+E18+E19 -> 7.6143707e+08 | F20: =F17+F18+F19 -> 8.0174717e+08 | G20: 7.9149898e+08 | H20: 7.4911176e+08 | I20: 9.0062587e+08 | J20: 1.0006994e+09 | K20: 1.0951694e+09 | L20: 1.0477135e+09 | M20: =M17+M18+M19 -> 881308487 | N20: 8.0545717e+08 | O20: =O17+O18+O19 -> 1.2847524e+09
A21: 6) | B21: Utility Sold Unit (Total)
A22: i) | B22: BPDB | C22: =C20 -> 1.0240537e+09 | D22: =D20 -> 844558097 | E22: =E20 -> 7.6143707e+08 | F22: 8.0174717e+08 | G22: 7.9149898e+08 | H22: 7.4911176e+08 | I22: 9.0062587e+08 | J22: 1.0006994e+09 | K22: 1.0951694e+09 | L22: 1.0477135e+09 | M22: =M20 -> 881308487 | N22: 8.0545717e+08 | O22: =O20 -> 1.2847524e+09
A23: ii) | B23: DPDC | C23: 8.8519625e+08 | D23: 754634392 | E23: 655913663 | F23: 640038166 | G23: 6.327447e+08 | H23: 550818616 | I23: 6.5261986e+08 | J23: 8.1025548e+08 | K23: 8.8949551e+08 | L23: 8.2455026e+08 | M23: 634507239 | N23: 617768603 | O23: =Comparison!D28 -> 9.4899702e+08
A24: iii) | B24: DESCO | C24: 5.2770857e+08 | D24: 431008192 | E24: 348534086 | F24: 333758470 | G24: 3.3336106e+08 | H24: 368583379 | I24: 4.314173e+08 | J24: 4.9543924e+08 | K24: 5.2898883e+08 | L24: 5.1493176e+08 | M24: 338548698 | N24: 333417748 | O24: =Comparison!D29 -> 6.7259079e+08
A25: iv) | B25: NESCO | C25: 338275734 | D25: 280577375 | E25: 279065557 | F25: 292119421 | G25: 282295647 | H25: 2.8744825e+08 | I25: 3.0401207e+08 | J25: 3.7080281e+08 | K25: 391674396 | L25: 4.0101463e+08 | M25: 296415360 | N25: 2.7933284e+08 | O25: =Comparison!D33 -> 501761025
A26: v) | B26: WZPDCL | C26: 314391233 | D26: 243432331 | E26: 234751697 | F26: 240865981 | G26: 233050903 | H26: 253931454 | I26: 283740681 | J26: 3.2554678e+08 | K26: 3.5024501e+08 | L26: 3.4017477e+08 | M26: 242156000 | N26: 2.2600103e+08 | O26: =Comparison!D30 -> 416348143
A27: vi) | B27: PBS | C27: 3.0383315e+09 | D27: 2330457326 | E27: 2232601351 | F27: 2.3594538e+09 | G27: 2.4433723e+09 | H27: 2.5950592e+09 | I27: 2.8976309e+09 | J27: 3.4008932e+09 | K27: 3.7354042e+09 | L27: 3.8703897e+09 | M27: 2684885996 | N27: 2.6003575e+09 | O27: =Summary!C18 -> 5.2348112e+09
A28: Total Sold Unit | C28: =SUM(C22:C27) -> 6.127957e+09 | D28: =SUM(D22:D27) -> 4884667713 | E28: =SUM(E22:E27) -> 4.5123034e+09 | F28: =SUM(F22:F27) -> 4.667983e+09 | G28: 4.7163235e+09 | H28: 4.8049526e+09 | I28: 5.4700467e+09 | J28: 6.4036369e+09 | K28: 6.9909774e+09 | L28: 6.9987746e+09 | M28: =SUM(M22:M27) -> 5077821780 | N28: 4.8623349e+09 | O28: =SUM(O22:O27) -> 9.0592605e+09
A29: 7) | B29: Transmission Loss in KWH | C29: =C8-C28 -> 1.3557989e+08 | D29: =D8-D28 -> 113504568 | E29: =E8-E28 -> 1.3905146e+08 | F29: =F8-F28 -> 1.1445332e+08 | G29: 1.1192468e+08 | H29: 1.221961e+08 | I29: 1.3949589e+08 | J29: 1.8068164e+08 | K29: 1.6237062e+08 | L29: 1.8759808e+08 | M29: =M8-M28 -> 156259537 | N29: 1.196976e+08 | O29: =O8-O28 -> 2.4901858e+08
A30: 8) | B30: % Transmission Loss | C30: =C29/C8*100 -> 2.1645899 | D30: =D29/D8*100 -> 2.2709215 | E30: =E29/E8*100 -> 2.9894828 | F30: =F29/F8*100 -> 2.3932012 | G30: 2.318122 | H30: 2.4800571 | I30: 2.4867605 | J30: 2.7441206 | K30: 2.2698548 | L30: 2.6104697 | M30: =M29/M8*100 -> 2.9854243 | N30: 2.4025858 | O30: =O29/O8*100 -> 2.6752375

Sheet Entry
E4: ='Gen-Ind'!H3 -> Month: June/2025
B5: SL | C5: EAUD | D5: BPDB | E5: PBS | F5: NESCO | G5: WZPDCL | H5: DESCO | I5: DPDC | J5: 230/132kV | K5: GENERATION
B6: 1 | C6: Dhaka | D6: - | E6: =Comparison!D50 -> 1.4843885e+09 | H6: =Comparison!D29 -> 6.7259079e+08 | I6: =Comparison!D28 -> 9.4899702e+08 | K6: =Diff!C6 -> 1.600638e+09
B7: 2 | C7: Ctg-1 | D7: =Comparison!D24 -> 448293825 | E7: =199459986+32885803 -> 232345789 | K7: =Diff!C8 -> 22559610
B8: 3 | C8: Ctg-3 | K8: =Diff!C9 -> 1.2215813e+09
B9: 4 | C9: Cumilla | D9: =Comparison!D17 -> 209581684 | E9: 514172168 | K9: =Diff!C10 -> 1.0623916e+09
B10: 5 | C10: Mymensingh | D10: =Comparison!D11 -> 277742112 | E10: 404738415 | K10: =Diff!C7 -> 1.9484165e+08
B11: 6 | C11: Barisal | D11: - | J11: =Comparison!D26 -> 2.2044575e+08 | K11: =Diff!C17 -> 1.215185e+09
B12: 7 | C12: Khulna | D12: - | E12: =Comparison!D31 -> 993769293 | G12: =Comparison!D30 -> 416348143 | K12: =Diff!C15 -> 6.5230822e+08
B13: 8 | C13: Jessore | D13: - | K13: =Diff!C16 -> 7.7626197e+08
B14: 9 | C14: Rajshahi | D14: - | K14: =Diff!C12 -> 7.5854766e+08
B15: 10 | C15: Rangpur | D15: - | E15: =Comparison!D34 -> 1066370426 | F15: =Comparison!D33 -> 501761025 | K15: =Diff!C14 -> 2.7089971e+08
B16: 11 | C16: Bogra | D16: - | K16: =Diff!C13 -> 5.7047088e+08
B17: 12 | C17: Sylhet | D17: =Comparison!D14 -> 125004929 | E17: 171086079 | K17: =Diff!C11 -> 9.6259358e+08
D18: =SUM(D6:D17)*0+947106736 -> 947106736 | E18: =SUM(E6:E17) -> 4.8668706e+09 | F18: =SUM(F6:F17) -> 501761025 | G18: =SUM(G6:G17) -> 416348143 | H18: =SUM(H6:H17) -> 6.7259079e+08 | I18: =SUM(I6:I17) -> 9.4899702e+08 | J18: =SUM(J6:J17) -> 2.2044575e+08 | K18: =SUM(K6:K17) -> 9.3082791e+09
D21: Total Generation | F21: =K18 -> 9.3082791e+09
D22: Total sale's | F22: =D18+E18+F18+G18+H18+I18+J18 -> 8.5741201e+09
D23: Loss | F23: =(F21-F22)/F21 -> 0.078871616

Sheet Adani Gen
A4: GSUT Unit-1 (Main)
A5: 1496 MW Adani PP | B5: Gross Generatrion | G5: Station Use | L5: Net Generation
B6: Previous | C6: 2023-01-01 | D6: Diff | E6: OMF | F6: Unit (kwh) | G6: =B6 -> Previous | H6: =C6 -> 2023-01-01 | I6: Diff | J6: OMF | K6: Unit (kwh) | L6: Unit (kwh)
B7: 9.23 | C7: 733.95 | D7: =C7-B7 -> 724.72 | E7: 5454545.5 | F7: =D7*E7/1000 -> 3953018.2 | G7: 1112.06 | H7: 1686.77 | I7: =H7-G7 -> 574.71 | J7: 5454545.5 | K7: =I7*J7/1000 -> 3134781.8 | L7: =F7-K7 -> 818236.36
A9: GSUT Unit-2 (Main)
A10: 1496 MW Adani PP | B10: Gross Generatrion | G10: Station Use | L10: Net Generation
B11: =B6 -> Previous | C11: =C6 -> 2023-01-01 | D11: Diff | E11: OMF | F11: Unit (kwh) | G11: =B6 -> Previous | H11: =C6 -> 2023-01-01 | I11: Diff | J11: OMF | K11: Unit (kwh) | L11: Unit (kwh)
B12: 0 | C12: 0 | D12: =C12-B12 -> 0 | E12: 5454545.5 | F12: =D12*E12/1000 -> 0 | G12: 13.92 | H12: 13.92 | I12: =H12-G12 -> 0 | J12: 5454545.5 | K12: =I12*J12/1000 -> 0 | L12: =F12-K12 -> 0
A14: SMT (Main)
A15: 1496 MW Adani PP | B15: Gross Generatrion | G15: Station Use | L15: Net Generation
B16: =B11 -> Previous | C16: =C11 -> 2023-01-01 | D16: Diff | E16: OMF | F16: Unit (kwh) | G16: =B11 -> Previous | H16: =C11 -> 2023-01-01 | I16: Diff | J16: OMF | K16: Unit (kwh) | L16: Unit (kwh)
B17: 0 | C17: 0 | D17: =C17-B17 -> 0 | E17: 363636.36 | F17: =D17*E17/1000 -> 0 | G17: 25379.90 | H17: 26558.99 | I17: =H17-G17 -> 1179.09 | J17: 363636.36 | K17: =I17*J17/1000 -> 428760 | L17: =F17-K17 -> -428760
C19: Gross Generation | H19: =F7+F12+F17 -> 3953018.2
C20: Station Use | H20: =K7+K12+K17 -> 3563541.8
C21: Net Generation | H21: =H19-H20 -> 389476.36
C22: Difference Between Main & Back Up for Unit -1 | H22: =L7-L27 -> -381.81818
A24: Unit-1 (Check)
A25: 1496 MW Adani PP | B25: Gross Generatrion | G25: Station Use | L25: Net Generation
B26: =B6 -> Previous | C26: =C6 -> 2023-01-01 | D26: Diff | E26: OMF | F26: Unit (kwh) | G26: =B6 -> Previous | H26: =C6 -> 2023-01-01 | I26: Diff | J26: OMF | K26: Unit (kwh) | L26: Unit (kwh)
B27: 9.23 | C27: 733.87 | D27: =C27-B27 -> 724.64 | E27: 5454545.5 | F27: =D27*E27/1000 -> 3952581.8 | G27: 1096.61 | H27: 1671.17 | I27: =H27-G27 -> 574.56 | J27: 5454545.5 | K27: =I27*J27/1000 -> 3133963.6 | L27: =F27-K27 -> 818618.18
A29: Unit-2 (Check)
A30: 1496 MW Adani PP | B30: Gross Generatrion | G30: Station Use | L30: Net Generation
B31: =B6 -> Previous | C31: =C6 -> 2023-01-01 | D31: Diff | E31: OMF | F31: Unit (kwh) | G31: =B6 -> Previous | H31: =C6 -> 2023-01-01 | I31: Diff | J31: OMF | K31: Unit (kwh) | L31: Unit (kwh)
B32: 0 | C32: 0 | D32: =C32-B32 -> 0 | E32: 5454545.5 | F32: =D32*E32/1000 -> 0 | G32: 16.37 | H32: 16.37 | I32: =H32-G32 -> 0 | J32: 5454545.5 | K32: =I32*J32/1000 -> 0 | L32: =F32-K32 -> 0
A34: SMT (Check)
A35: 1496 MW Adani PP | B35: Gross Generatrion | G35: Station Use | L35: Net Generation
B36: =B31 -> Previous | C36: =C31 -> 2023-01-01 | D36: Diff | E36: OMF | F36: Unit (kwh) | G36: =B31 -> Previous | H36: =C31 -> 2023-01-01 | I36: Diff | J36: OMF | K36: Unit (kwh) | L36: Unit (kwh)
B37: 0 | C37: 0 | D37: =C37-B37 -> 0 | E37: 363636.36 | F37: =D37*E37/1000 -> 0 | G37: 25371.54 | H37: 26550.13 | I37: =H37-G37 -> 1178.59 | J37: 363636.36 | K37: =I37*J37/1000 -> 428578.18 | L37: =F37-K37 -> -428578.18

Sheet Sheet1
D2: Bill Month : | E2: 45383
A3: SL | B3: Utility | C3: Billed Amount | D3: AIT | E3: Net Bill Total | F3: Last Payment Date
B4: 1 | C4: 2 | D4: 3 | E4: 4 | F4: 5
A5: 1 | B5: BPDB | C5: =Comparison!D25*7.2895 -> 7.7314081e+09 | E5: =C5 -> 7.7314081e+09
A6: 2 | B6: DPDC | C6: 8342412351 | D6: 500544741 | E6: =C6-D6 -> 7841867610 | F6: 45453
A7: 3 | B7: DESCO | C7: 5949631939 | D7: 356977916 | E7: =C7-D7 -> 5592654023 | F7: 45453
A8: 4 | B8: NESCO | C8: 3173581729 | D8: 190414904 | E8: =C8-D8 -> 2983166825 | F8: 45453
A9: 5 | B9: WZPDCL | C9: 3072303035 | D9: 184338182 | E9: =C9-D9 -> 2887964853 | F9: 45453
A10: 6 | B10: PBS | C10: =31082558025+616371 -> 31083174396 | D10: 1864953481 | E10: =C10-D10 -> 29218220915 | F10: 45452
A11: 7 | B11: 132&230kV Consumer | C11: 2154708264 | E11: =C11 -> 2154708264
A12: Total | C12: =SUM(C5:C11) -> 6.150722e+10 | D12: =SUM(D5:D11) -> 3097229224 | E12: =C12-D12 -> 5.8409991e+10
